# R√©solution du Crash Agent - AudioEmitter TypeError

## Probl√®me Identifi√©

**Erreur** : `TypeError: 'AudioEmitter' object is not callable`

**Localisation** : `services/api-backend/services/real_time_voice_agent_force_audio_fixed.py`, ligne 292

**Cause** : Le code tentait d'appeler `output_emitter()` comme une fonction, alors que `AudioEmitter` est un objet avec des m√©thodes sp√©cifiques.

## Diagnostic Effectu√©

1. **Analyse des logs** :
   - L'erreur se produisait lors de la g√©n√©ration TTS
   - Le crash emp√™chait l'agent de r√©pondre avec de l'audio

2. **Inspection de l'API AudioEmitter** :
   - `AudioEmitter` n'est pas directement callable
   - M√©thodes disponibles : `push()`, `initialize()`, `start_segment()`, `end_segment()`, `flush()`

3. **Identification de la source** :
   - Mauvaise utilisation de l'API dans la m√©thode `_run()` de `LocalOpenAITTSStream`
   - Code incorrect : `await output_emitter(audio_data)`
   - Code correct : `await output_emitter.push(audio_data)`

## Correction Appliqu√©e

### Changements dans `real_time_voice_agent_force_audio_fixed.py`

1. **M√©thode `_run()` corrig√©e** (lignes 247-329) :
   ```python
   async def _run(self, output_emitter: 'AudioEmitter') -> None:
       # Ajout de logs de debug
       logger.debug(f"üîç [TTS] Type d'output_emitter: {type(output_emitter)}")
       
       # Initialisation si n√©cessaire
       if hasattr(output_emitter, 'initialize'):
           await output_emitter.initialize()
       
       # D√©marrage du segment audio
       if hasattr(output_emitter, 'start_segment'):
           await output_emitter.start_segment()
       
       # Envoi des chunks audio avec push()
       for i in range(0, len(audio_data), chunk_size):
           chunk = audio_data[i : i + chunk_size]
           await output_emitter.push(chunk)  # ‚úÖ Utilisation correcte
           await asyncio.sleep(0.01)
       
       # Fin du segment et flush
       if hasattr(output_emitter, 'end_segment'):
           await output_emitter.end_segment()
       if hasattr(output_emitter, 'flush'):
           await output_emitter.flush()
   ```

2. **Gestion d'erreur am√©lior√©e** :
   - Utilisation de `push()` aussi pour l'envoi du silence en cas d'erreur
   - Ajout de try/catch autour des appels √† l'AudioEmitter

## V√©rification de la Correction

### Commandes de v√©rification :

```bash
# V√©rifier que le fichier est bien mis √† jour dans le conteneur
docker exec 25eloquence-finalisation-eloquence-agent-v1-1 grep -n "push(" /app/services/real_time_voice_agent_force_audio_fixed.py

# Surveiller les logs pour l'absence de l'erreur
docker logs -f 25eloquence-finalisation-eloquence-agent-v1-1 --tail 50

# Rechercher sp√©cifiquement les erreurs AudioEmitter
docker logs 25eloquence-finalisation-eloquence-agent-v1-1 2>&1 | grep -i "audioemitter"
```

### Indicateurs de succ√®s :

1. ‚úÖ Plus d'erreur `TypeError: 'AudioEmitter' object is not callable`
2. ‚úÖ Logs montrant : `‚úÖ [TTS] Audio g√©n√©r√© avec succ√®s: X bytes`
3. ‚úÖ L'agent r√©pond avec de l'audio dans l'application

## Impact de la Correction

- **Avant** : L'agent crashait lors de la g√©n√©ration TTS, pas de r√©ponse audio
- **Apr√®s** : L'agent peut g√©n√©rer et envoyer l'audio correctement

## Recommandations

1. **Test complet** : Tester avec l'application Flutter pour confirmer la r√©ception audio
2. **Monitoring** : Surveiller les logs pendant 24h pour s'assurer de la stabilit√©
3. **Documentation** : Mettre √† jour la documentation de l'API custom si n√©cessaire

## Le√ßons Apprises

1. **Toujours v√©rifier l'API** : Les objets peuvent avoir des m√©thodes sp√©cifiques plut√¥t que d'√™tre directement callables
2. **Logs de debug** : Ajouter des logs pour identifier le type et les m√©thodes disponibles
3. **Gestion d'erreur robuste** : Pr√©voir des fallbacks m√™me dans les gestionnaires d'erreur

---

**Date de r√©solution** : 03/07/2025
**Version livekit-agents** : 1.1.5
**Fichier modifi√©** : `services/api-backend/services/real_time_voice_agent_force_audio_fixed.py`